werkzeug - INFO -  * Running on http://127.0.0.1:5000/ (Press CTRL+C to quit)
personal_website.app - ERROR - Exception on / [GET]
Traceback (most recent call last):
  File "/opt/anaconda3/lib/python3.7/site-packages/flask/app.py", line 2446, in wsgi_app
    response = self.full_dispatch_request()
  File "/opt/anaconda3/lib/python3.7/site-packages/flask/app.py", line 1951, in full_dispatch_request
    rv = self.handle_user_exception(e)
  File "/opt/anaconda3/lib/python3.7/site-packages/flask/app.py", line 1820, in handle_user_exception
    reraise(exc_type, exc_value, tb)
  File "/opt/anaconda3/lib/python3.7/site-packages/flask/_compat.py", line 39, in reraise
    raise value
  File "/opt/anaconda3/lib/python3.7/site-packages/flask/app.py", line 1949, in full_dispatch_request
    rv = self.dispatch_request()
  File "/opt/anaconda3/lib/python3.7/site-packages/flask/app.py", line 1935, in dispatch_request
    return self.view_functions[rule.endpoint](**req.view_args)
  File "/Users/emadsiddiq/Projects/personal_website/resume/resume.py", line 10, in home
    return render_template('resume-format-home.html')
  File "/opt/anaconda3/lib/python3.7/site-packages/flask/templating.py", line 140, in render_template
    ctx.app,
  File "/opt/anaconda3/lib/python3.7/site-packages/flask/templating.py", line 120, in _render
    rv = template.render(context)
  File "/opt/anaconda3/lib/python3.7/site-packages/jinja2/environment.py", line 1090, in render
    self.environment.handle_exception()
  File "/opt/anaconda3/lib/python3.7/site-packages/jinja2/environment.py", line 832, in handle_exception
    reraise(*rewrite_traceback_stack(source=source))
  File "/opt/anaconda3/lib/python3.7/site-packages/jinja2/_compat.py", line 28, in reraise
    raise value.with_traceback(tb)
  File "/Users/emadsiddiq/Projects/personal_website/resume/templates/resume-format-home.html", line 34, in top-level template code
    <a href="{{url_for('resume_bp.data',filename='Emad_Resume.pdf')}}" target="_blank"><button type="button" class="btn btn-link">Resume</button></a>
  File "/opt/anaconda3/lib/python3.7/site-packages/flask/helpers.py", line 370, in url_for
    return appctx.app.handle_url_build_error(error, endpoint, values)
  File "/opt/anaconda3/lib/python3.7/site-packages/flask/app.py", line 2215, in handle_url_build_error
    reraise(exc_type, exc_value, tb)
  File "/opt/anaconda3/lib/python3.7/site-packages/flask/_compat.py", line 39, in reraise
    raise value
  File "/opt/anaconda3/lib/python3.7/site-packages/flask/helpers.py", line 358, in url_for
    endpoint, values, method=method, force_external=external
  File "/opt/anaconda3/lib/python3.7/site-packages/werkzeug/routing.py", line 2179, in build
    raise BuildError(endpoint, values, method, self)
werkzeug.routing.BuildError: Could not build url for endpoint 'resume_bp.data' with values ['filename']. Did you mean 'resume_bp.static' instead?
werkzeug - INFO - 127.0.0.1 - - [19/Aug/2020 14:54:01] "[35m[1mGET / HTTP/1.1[0m" 500 -
werkzeug - INFO - 127.0.0.1 - - [19/Aug/2020 14:54:01] "[33mGET /favicon.ico HTTP/1.1[0m" 404 -
